<?xml version="1.0" ?>
<!-- =================================================================================== -->
<!-- |    This document was autogenerated by xacro from minitaur.urdf.xacro            | -->
<!-- |    EDITING THIS FILE BY HAND IS NOT RECOMMENDED                                 | -->
<!-- =================================================================================== -->
<!-- ======================================================================= -->
<!--LICENSE:                                                                 -->
<!--Copyright (c) 2017, Erwin Coumans                                        -->
<!--Google Inc.                                                              -->
<!--All rights reserved.                                                     -->
<!--                                                                         -->
<!--Redistribution and use in source and binary forms, with or without       -->
<!--modification, are permitted provided that the following conditions are   -->
<!--met:                                                                     -->
<!--                                                                         -->
<!--1. Redistributions or derived work must retain this copyright notice,    -->
<!--   this list of conditions and the following disclaimer.                 -->
<!--                                                                         -->
<!--2. Redistributions in binary form must reproduce the above copyright     -->
<!--   notice, this list of conditions and the following disclaimer in the   -->
<!--   documentation and/or other materials provided with the distribution.  -->
<!--                                                                         -->
<!--THIS SOFTWARE IS PROVIDED BY THE COPYRIGHT HOLDERS AND CONTRIBUTORS "AS  -->
<!--IS" AND ANY EXPRESS OR IMPLIED WARRANTIES, INCLUDING, BUT NOT LIMITED TO,-->
<!--THE IMPLIED WARRANTIES OF MERCHANTABILITY AND FITNESS FOR A PARTICULAR   -->
<!--PURPOSE ARE DISCLAIMED. IN NO EVENT SHALL THE COPYRIGHT HOLDER OR        -->
<!--CONTRIBUTORS BE LIABLE FOR ANY DIRECT, INDIRECT, INCIDENTAL, SPECIAL,    -->
<!--EXEMPLARY, OR CONSEQUENTIAL DAMAGES (INCLUDING, BUT NOT LIMITED TO,      -->
<!--PROCUREMENT OF SUBSTITUTE GOODS OR SERVICES; LOSS OF USE, DATA, OR       -->
<!--PROFITS; OR BUSINESS INTERRUPTION) HOWEVER CAUSED AND ON ANY THEORY OF   -->
<!--LIABILITY, WHETHER IN CONTRACT, STRICT LIABILITY, OR TORT (INCLUDING     -->
<!--NEGLIGENCE OR OTHERWISE) ARISING IN ANY WAY OUT OF THE USE OF THIS       -->
<!--SOFTWARE, EVEN IF ADVISED OF THE POSSIBILITY OF SUCH DAMAGE.             -->
<!--                                                                         -->
<!-- Converted to xacro by Tom Jacobs <tom.jacobs@ghostrobotics.io>          -->
<robot name="minitaur" xmlns:xacro="http://www.ros.org/wiki/xacro">
  <!-- Define parameters -->
  <!-- 7.18kg minitaur total weight - 0.016*4 - 0.10*8 - 0.25*8 - 0.05*8 - 0.05*8 = 3.516 -->
  <!-- * 4 frames -->
  <!-- * 8 motor modules -->
  <!-- * 8 motors -->
  <!-- * 8 upper legs -->
  <!-- * 8 lower legs -->
  <!-- Define materials -->
  <material name="black">
    <color rgba="0.3 0.3 0.3 1"/>
  </material>
  <material name="grey">
    <color rgba="0.5 0.5 0.5 1"/>
  </material>
  <material name="frameGrey">
    <color rgba="0.55 0.55 0.55 1"/>
  </material>
  <material name="legGrey">
    <color rgba="0.65 0.65 0.75 1"/>
  </material>
  <material name="motor">
    <color rgba="0.2 0.2 0.2 1"/>
  </material>
  <!-- Body -->
  <link name="base_chassis_link">
    <visual>
      <geometry>
        <box size="0.33 0.1855 0.08"/>
      </geometry>
      <material name="black"/>
    </visual>
    <visual>
      <origin rpy="0 0 0" xyz="0 0.10 -0.014"/>
      <geometry>
        <box size="0.17 0.1 0.05"/>
      </geometry>
      <material name="black"/>
    </visual>
    <visual>
      <origin rpy="0 0 0" xyz="0 -0.10 -0.014"/>
      <geometry>
        <box size="0.17 0.1 0.05"/>
      </geometry>
      <material name="black"/>
    </visual>
    <collision>
      <geometry>
        <box size="0.33 0.1855 0.08"/>
      </geometry>
    </collision>
    <collision>
      <origin rpy="0 0 0" xyz="0 0.10 -0.014"/>
      <geometry>
        <box size="0.17 0.1 0.05"/>
      </geometry>
    </collision>
    <collision>
      <origin rpy="0 0 0" xyz="0 -0.10 -0.014"/>
      <geometry>
        <box size="0.17 0.1 0.05"/>
      </geometry>
    </collision>
    <inertial>
      <mass value="3.516"/>
      <!-- https://en.wikipedia.org/wiki/List_of_moments_of_inertia Solid Cuboid -->
      <inertia ixx="0.01195740325" ixy="0.0" ixz="0.0" iyy="0.0337829" iyz="0.0" izz="0.04198990325"/>
    </inertial>
  </link>
  <!-- Frame -->
  <link name="frame1">
    <visual>
      <origin rpy="0 0 0" xyz="-0.22 0 0"/>
      <geometry>
        <box size="0.468 .012 .050"/>
      </geometry>
      <material name="frameGrey"/>
    </visual>
    <collision>
      <origin rpy="0 0 0" xyz="-0.22 0 0"/>
      <geometry>
        <box size="0.468 .012 .050"/>
      </geometry>
    </collision>
    <inertial>
      <origin rpy="0 0 0" xyz="0 -0.03 0"/>
      <mass value="0.16"/>
      <inertia ixx=".00011397" ixy=".0" ixz=".0" iyy=".00011397" iyz=".0" izz=".00021765"/>
    </inertial>
  </link>
  <joint name="frame1_joint" type="fixed">
    <axis xyz="0 0 1"/>
    <parent link="base_chassis_link"/>
    <child link="frame1"/>
    <origin rpy="0 0 0" xyz=".2375 -0.154 -.0185"/>
    <limit effort="100" velocity="100"/>
    <joint_properties damping=".0" friction=".0"/>
  </joint>
  <link name="frame2">
    <visual>
      <origin rpy="0 0 0" xyz="-0.22 0 0"/>
      <geometry>
        <box size="0.468 .012 .050"/>
      </geometry>
      <material name="frameGrey"/>
    </visual>
    <collision>
      <origin rpy="0 0 0" xyz="-0.22 0 0"/>
      <geometry>
        <box size="0.468 .012 .050"/>
      </geometry>
    </collision>
    <inertial>
      <origin rpy="0 0 0" xyz="0 0.02 0"/>
      <mass value="0.16"/>
      <inertia ixx=".00011397" ixy=".0" ixz=".0" iyy=".00011397" iyz=".0" izz=".00021765"/>
    </inertial>
  </link>
  <joint name="frame2_joint" type="fixed">
    <axis xyz="0 0 1"/>
    <parent link="base_chassis_link"/>
    <child link="frame2"/>
    <origin rpy="0 0 0" xyz=".2375 0.154 -.0185"/>
    <limit effort="100" velocity="100"/>
    <joint_properties damping=".0" friction=".0"/>
  </joint>
  <link name="frame3">
    <visual>
      <origin rpy="0 0 0" xyz="0.22 0.055 0"/>
      <geometry>
        <box size="0.468 .012 .050"/>
      </geometry>
      <material name="frameGrey"/>
    </visual>
    <collision>
      <origin rpy="0 0 0" xyz="0.22 0.055 0"/>
      <geometry>
        <box size="0.468 .012 .050"/>
      </geometry>
    </collision>
    <inertial>
      <origin rpy="0 0 0" xyz="0 -0.03 0"/>
      <mass value="0.16"/>
      <inertia ixx=".00011397" ixy=".0" ixz=".0" iyy=".00011397" iyz=".0" izz=".00021765"/>
    </inertial>
  </link>
  <joint name="frame3_joint" type="fixed">
    <axis xyz="0 0 1"/>
    <parent link="base_chassis_link"/>
    <child link="frame3"/>
    <origin rpy="0 0 0" xyz="-.2375 -0.154 -.0185"/>
    <limit effort="100" velocity="100"/>
    <joint_properties damping=".0" friction=".0"/>
  </joint>
  <link name="frame4">
    <visual>
      <origin rpy="0 0 0" xyz="0.22 -0.055 0"/>
      <geometry>
        <box size="0.468 .012 .050"/>
      </geometry>
      <material name="frameGrey"/>
    </visual>
    <collision>
      <origin rpy="0 0 0" xyz="0.22 -0.055 0"/>
      <geometry>
        <box size="0.468 .012 .050"/>
      </geometry>
    </collision>
    <inertial>
      <origin rpy="0 0 0" xyz="0 0.02 0"/>
      <mass value="0.16"/>
      <inertia ixx=".00011397" ixy=".0" ixz=".0" iyy=".00011397" iyz=".0" izz=".00021765"/>
    </inertial>
  </link>
  <joint name="frame4" type="fixed">
    <axis xyz="0 0 1"/>
    <parent link="base_chassis_link"/>
    <child link="frame4"/>
    <origin rpy="0 0 0" xyz="-.2375 0.154 -.0185"/>
    <limit effort="100" velocity="100"/>
    <joint_properties damping=".0" friction=".0"/>
  </joint>
  <!-- Inside motor module boxes -->
  <link name="chassis_right">
    <visual>
      <origin rpy="0 0 0" xyz=".2375 .049 0"/>
      <geometry>
        <box size=".068 .032 .050"/>
      </geometry>
      <material name="motor"/>
    </visual>
    <visual>
      <origin rpy="0 0 0" xyz="-.2375 .049 0"/>
      <geometry>
        <box size=".068 .032 .050"/>
      </geometry>
      <material name="motor"/>
    </visual>
    <collision>
      <origin rpy="0 0 0" xyz=".2375 .049 0"/>
      <geometry>
        <box size=".068 .032 .050"/>
      </geometry>
    </collision>
    <collision>
      <origin rpy="0 0 0" xyz="-.2375 .049 0"/>
      <geometry>
        <box size=".068 .032 .050"/>
      </geometry>
    </collision>
    <inertial>
      <mass value="0.2"/>
      <inertia ixx=".004147" ixy=".0" ixz=".0" iyy=".040913" iyz=".0" izz=".041840"/>
    </inertial>
  </link>
  <joint name="chassis_right_center" type="fixed">
    <axis xyz="0 0 1"/>
    <parent link="base_chassis_link"/>
    <child link="chassis_right"/>
    <origin rpy="0 0 0" xyz="0 -.1265 -.0185"/>
    <limit effort="100" velocity="100"/>
    <joint_properties damping=".0" friction=".0"/>
  </joint>
  <link name="chassis_left">
    <visual>
      <origin rpy="0 0 0" xyz=".2375 -.049 0"/>
      <geometry>
        <box size=".068 .032 .050"/>
      </geometry>
      <material name="motor"/>
    </visual>
    <visual>
      <origin rpy="0 0 0" xyz="-.2375 -.049 0"/>
      <geometry>
        <box size=".068 .032 .050"/>
      </geometry>
      <material name="motor"/>
    </visual>
    <collision>
      <origin rpy="0 0 0" xyz=".2375 -.049 0"/>
      <geometry>
        <box size=".068 .032 .050"/>
      </geometry>
    </collision>
    <collision>
      <origin rpy="0 0 0" xyz="-.2375 -.049 0"/>
      <geometry>
        <box size=".068 .032 .050"/>
      </geometry>
    </collision>
    <inertial>
      <mass value="0.2"/>
      <inertia ixx=".004147" ixy=".0" ixz=".0" iyy=".040913" iyz=".0" izz=".041840"/>
    </inertial>
  </link>
  <joint name="chassis_left_center" type="fixed">
    <axis xyz="0 0 1"/>
    <parent link="base_chassis_link"/>
    <child link="chassis_left"/>
    <origin rpy="0 0 0" xyz="0 .1265 -.0185"/>
    <limit effort="100" velocity="100"/>
    <joint_properties damping=".0" friction=".0"/>
  </joint>
  <!-- Outside motor module boxes -->
  <link name="motor_front_rightR_bracket_link">
    <visual>
      <origin rpy="0 0 0" xyz="0 -0.02 0"/>
      <geometry>
        <box size="0.068 .032 .050"/>
      </geometry>
      <material name="motor"/>
    </visual>
    <collision>
      <origin rpy="0 0 0" xyz="0 -0.02 0"/>
      <geometry>
        <box size=".068 .032 .050"/>
      </geometry>
    </collision>
    <inertial>
      <origin rpy="0 0 0" xyz="0 -0.03 0"/>
      <mass value="0.1"/>
      <inertia ixx=".00011397" ixy=".0" ixz=".0" iyy=".00011397" iyz=".0" izz=".00021765"/>
    </inertial>
  </link>
  <joint name="motor_front_rightR_bracket_joint" type="fixed">
    <axis xyz="0 0 1"/>
    <parent link="base_chassis_link"/>
    <child link="motor_front_rightR_bracket_link"/>
    <origin rpy="0 0 0" xyz=".2375 -0.154 -.0185"/>
    <limit effort="100" velocity="100"/>
    <joint_properties damping=".0" friction=".0"/>
  </joint>
  <link name="motor_front_leftL_bracket_link">
    <visual>
      <origin rpy="0 0 0" xyz="0 0.02 0"/>
      <geometry>
        <box size="0.068 .032 .050"/>
      </geometry>
      <material name="motor"/>
    </visual>
    <collision>
      <origin rpy="0 0 0" xyz="0 0.02 0"/>
      <geometry>
        <box size=".068 .032 .050"/>
      </geometry>
    </collision>
    <inertial>
      <origin rpy="0 0 0" xyz="0 0.02 0"/>
      <mass value="0.1"/>
      <inertia ixx=".00011397" ixy=".0" ixz=".0" iyy=".00011397" iyz=".0" izz=".00021765"/>
    </inertial>
  </link>
  <joint name="motor_front_leftL_bracket_joint" type="fixed">
    <axis xyz="0 0 1"/>
    <parent link="base_chassis_link"/>
    <child link="motor_front_leftL_bracket_link"/>
    <origin rpy="0 0 0" xyz=".2375 0.154 -.0185"/>
    <limit effort="100" velocity="100"/>
    <joint_properties damping=".0" friction=".0"/>
  </joint>
  <link name="motor_back_rightR_bracket_link">
    <visual>
      <origin rpy="0 0 0" xyz="0 -0.02 0"/>
      <geometry>
        <box size="0.068 .032 .050"/>
      </geometry>
      <material name="motor"/>
    </visual>
    <collision>
      <origin rpy="0 0 0" xyz="0 -0.02 0"/>
      <geometry>
        <box size=".068 .032 .050"/>
      </geometry>
    </collision>
    <inertial>
      <origin rpy="0 0 0" xyz="0 -0.03 0"/>
      <mass value="0.1"/>
      <inertia ixx=".00011397" ixy=".0" ixz=".0" iyy=".00011397" iyz=".0" izz=".00021765"/>
    </inertial>
  </link>
  <joint name="motor_back_rightR_bracket_joint" type="fixed">
    <axis xyz="0 0 1"/>
    <parent link="base_chassis_link"/>
    <child link="motor_back_rightR_bracket_link"/>
    <origin rpy="0 0 0" xyz="-.2375 -0.154 -.0185"/>
    <limit effort="100" velocity="100"/>
    <joint_properties damping=".0" friction=".0"/>
  </joint>
  <link name="motor_back_leftL_bracket_link">
    <visual>
      <origin rpy="0 0 0" xyz="0 0.02 0"/>
      <geometry>
        <box size="0.068 .032 .050"/>
      </geometry>
      <material name="motor"/>
    </visual>
    <collision>
      <origin rpy="0 0 0" xyz="0 0.02 0"/>
      <geometry>
        <box size=".068 .032 .050"/>
      </geometry>
    </collision>
    <inertial>
      <origin rpy="0 0 0" xyz="0 0.02 0"/>
      <mass value="0.1"/>
      <inertia ixx=".00011397" ixy=".0" ixz=".0" iyy=".00011397" iyz=".0" izz=".00021765"/>
    </inertial>
  </link>
  <joint name="motor_back_leftL_bracket_joint" type="fixed">
    <axis xyz="0 0 1"/>
    <parent link="base_chassis_link"/>
    <child link="motor_back_leftL_bracket_link"/>
    <origin rpy="0 0 0" xyz="-.2375 0.154 -.0185"/>
    <limit effort="100" velocity="100"/>
    <joint_properties damping=".0" friction=".0"/>
  </joint>
  <!-- Define our motor macro -->
  <!-- Motors -->
  <link name="motor_front_rightR_link">
    <visual>
      <geometry>
        <mesh filename="package://minitaur_description/meshes/tmotor3.obj" scale="1.0 1.0 1.0"/>
      </geometry>
      <material name="motor"/>
    </visual>
    <collision>
      <geometry>
        <cylinder length="0.021" radius="0.0425"/>
      </geometry>
    </collision>
    <inertial>
      <mass value="0.25"/>
      <inertia ixx=".00011397" ixy=".0" ixz=".0" iyy=".00011397" iyz=".0" izz=".00021765"/>
    </inertial>
  </link>
  <joint name="5" type="continuous">
    <axis xyz="0 0 1"/>
    <parent link="motor_front_rightR_bracket_link"/>
    <child link="motor_front_rightR_link"/>
    <origin rpy="1.57075 0 0" xyz="0 0 0"/>
    <limit effort="100" velocity="100"/>
    <joint_properties damping="0.0" friction="0.0"/>
  </joint>
  <link name="motor_front_rightL_link">
    <visual>
      <geometry>
        <mesh filename="package://minitaur_description/meshes/tmotor3.obj" scale="1.0 1.0 1.0"/>
      </geometry>
      <material name="motor"/>
    </visual>
    <collision>
      <geometry>
        <cylinder length="0.021" radius="0.0425"/>
      </geometry>
    </collision>
    <inertial>
      <mass value="0.25"/>
      <inertia ixx=".00011397" ixy=".0" ixz=".0" iyy=".00011397" iyz=".0" izz=".00021765"/>
    </inertial>
  </link>
  <joint name="4" type="continuous">
    <axis xyz="0 0 -1"/>
    <parent link="chassis_right"/>
    <child link="motor_front_rightL_link"/>
    <origin rpy="1.57075 0 0" xyz=".2375 .0275 0"/>
    <limit effort="100" velocity="100"/>
    <joint_properties damping="0.0" friction="0.0"/>
  </joint>
  <link name="motor_front_leftL_link">
    <visual>
      <geometry>
        <mesh filename="package://minitaur_description/meshes/tmotor3.obj" scale="1.0 1.0 1.0"/>
      </geometry>
      <material name="motor"/>
    </visual>
    <collision>
      <geometry>
        <cylinder length="0.021" radius="0.0425"/>
      </geometry>
    </collision>
    <inertial>
      <mass value="0.25"/>
      <inertia ixx=".00011397" ixy=".0" ixz=".0" iyy=".00011397" iyz=".0" izz=".00021765"/>
    </inertial>
  </link>
  <joint name="0" type="continuous">
    <axis xyz="0 0 -1"/>
    <parent link="motor_front_leftL_bracket_link"/>
    <child link="motor_front_leftL_link"/>
    <origin rpy="1.57075 0 0" xyz="0 0 0"/>
    <limit effort="100" velocity="100"/>
    <joint_properties damping="0.0" friction="0.0"/>
  </joint>
  <link name="motor_front_leftR_link">
    <visual>
      <geometry>
        <mesh filename="package://minitaur_description/meshes/tmotor3.obj" scale="1.0 1.0 1.0"/>
      </geometry>
      <material name="motor"/>
    </visual>
    <collision>
      <geometry>
        <cylinder length="0.021" radius="0.0425"/>
      </geometry>
    </collision>
    <inertial>
      <mass value="0.25"/>
      <inertia ixx=".00011397" ixy=".0" ixz=".0" iyy=".00011397" iyz=".0" izz=".00021765"/>
    </inertial>
  </link>
  <joint name="1" type="continuous">
    <axis xyz="0 0 1"/>
    <parent link="chassis_left"/>
    <child link="motor_front_leftR_link"/>
    <origin rpy="1.57075 0 0" xyz=".2375 -.0275 0"/>
    <limit effort="100" velocity="100"/>
    <joint_properties damping="0.0" friction="0.0"/>
  </joint>
  <link name="motor_back_rightR_link">
    <visual>
      <geometry>
        <mesh filename="package://minitaur_description/meshes/tmotor3.obj" scale="1.0 1.0 1.0"/>
      </geometry>
      <material name="motor"/>
    </visual>
    <collision>
      <geometry>
        <cylinder length="0.021" radius="0.0425"/>
      </geometry>
    </collision>
    <inertial>
      <mass value="0.25"/>
      <inertia ixx=".00011397" ixy=".0" ixz=".0" iyy=".00011397" iyz=".0" izz=".00021765"/>
    </inertial>
  </link>
  <joint name="7" type="continuous">
    <axis xyz="0 0 1"/>
    <parent link="motor_back_rightR_bracket_link"/>
    <child link="motor_back_rightR_link"/>
    <origin rpy="1.57075 0 0" xyz="0 0 0"/>
    <limit effort="100" velocity="100"/>
    <joint_properties damping="0.0" friction="0.0"/>
  </joint>
  <link name="motor_back_rightL_link">
    <visual>
      <geometry>
        <mesh filename="package://minitaur_description/meshes/tmotor3.obj" scale="1.0 1.0 1.0"/>
      </geometry>
      <material name="motor"/>
    </visual>
    <collision>
      <geometry>
        <cylinder length="0.021" radius="0.0425"/>
      </geometry>
    </collision>
    <inertial>
      <mass value="0.25"/>
      <inertia ixx=".00011397" ixy=".0" ixz=".0" iyy=".00011397" iyz=".0" izz=".00021765"/>
    </inertial>
  </link>
  <joint name="6" type="continuous">
    <axis xyz="0 0 -1"/>
    <parent link="chassis_right"/>
    <child link="motor_back_rightL_link"/>
    <origin rpy="1.57075 0 0" xyz="-.2375 .0275 0"/>
    <limit effort="100" velocity="100"/>
    <joint_properties damping="0.0" friction="0.0"/>
  </joint>
  <link name="motor_back_leftL_link">
    <visual>
      <geometry>
        <mesh filename="package://minitaur_description/meshes/tmotor3.obj" scale="1.0 1.0 1.0"/>
      </geometry>
      <material name="motor"/>
    </visual>
    <collision>
      <geometry>
        <cylinder length="0.021" radius="0.0425"/>
      </geometry>
    </collision>
    <inertial>
      <mass value="0.25"/>
      <inertia ixx=".00011397" ixy=".0" ixz=".0" iyy=".00011397" iyz=".0" izz=".00021765"/>
    </inertial>
  </link>
  <joint name="2" type="continuous">
    <axis xyz="0 0 -1"/>
    <parent link="motor_back_leftL_bracket_link"/>
    <child link="motor_back_leftL_link"/>
    <origin rpy="1.57075 0 0" xyz="0 0 0"/>
    <limit effort="100" velocity="100"/>
    <joint_properties damping="0.0" friction="0.0"/>
  </joint>
  <link name="motor_back_leftR_link">
    <visual>
      <geometry>
        <mesh filename="package://minitaur_description/meshes/tmotor3.obj" scale="1.0 1.0 1.0"/>
      </geometry>
      <material name="motor"/>
    </visual>
    <collision>
      <geometry>
        <cylinder length="0.021" radius="0.0425"/>
      </geometry>
    </collision>
    <inertial>
      <mass value="0.25"/>
      <inertia ixx=".00011397" ixy=".0" ixz=".0" iyy=".00011397" iyz=".0" izz=".00021765"/>
    </inertial>
  </link>
  <joint name="3" type="continuous">
    <axis xyz="0 0 1"/>
    <parent link="chassis_left"/>
    <child link="motor_back_leftR_link"/>
    <origin rpy="1.57075 0 0" xyz="-.2375 -.0275 0"/>
    <limit effort="100" velocity="100"/>
    <joint_properties damping="0.0" friction="0.0"/>
  </joint>
  <!-- Define our upper leg macro -->
  <!-- Define our lower leg macro -->
  <!-- Legs -->
  <link name="upper_leg_front_rightR_link">
    <visual>
      <geometry>
        <box size="0.039 0.008 0.1"/>
      </geometry>
      <material name="legGrey"/>
    </visual>
    <collision>
      <geometry>
        <box size="0.039 0.008 0.1"/>
      </geometry>
    </collision>
    <inertial>
      <mass value="0.05"/>
      <inertia ixx=".000038770" ixy=".0" ixz=".0" iyy=".000042198" iyz=".0" izz=".0000036030"/>
    </inertial>
  </link>
  <joint name="hip_front_rightR_link" type="fixed">
    <axis xyz="0 0 1"/>
    <parent link="motor_front_rightR_link"/>
    <child link="upper_leg_front_rightR_link"/>
    <origin rpy="-1.57075 0 0" xyz="0 .045 -.0145"/>
    <limit effort="100" velocity="100"/>
    <joint_properties damping="0.0" friction="0.0"/>
  </joint>
  <link name="upper_leg_front_rightL_link">
    <visual>
      <geometry>
        <box size="0.039 0.008 0.1"/>
      </geometry>
      <material name="legGrey"/>
    </visual>
    <collision>
      <geometry>
        <box size="0.039 0.008 0.1"/>
      </geometry>
    </collision>
    <inertial>
      <mass value="0.05"/>
      <inertia ixx=".000038770" ixy=".0" ixz=".0" iyy=".000042198" iyz=".0" izz=".0000036030"/>
    </inertial>
  </link>
  <joint name="motor_front_rightL_link" type="fixed">
    <axis xyz="0 0 1"/>
    <parent link="motor_front_rightL_link"/>
    <child link="upper_leg_front_rightL_link"/>
    <origin rpy="-1.57075 0 0" xyz="0 .045 .0145"/>
    <limit effort="100" velocity="100"/>
    <joint_properties damping="0.0" friction="0.0"/>
  </joint>
  <link name="upper_leg_front_leftR_link">
    <visual>
      <geometry>
        <box size="0.039 0.008 0.1"/>
      </geometry>
      <material name="legGrey"/>
    </visual>
    <collision>
      <geometry>
        <box size="0.039 0.008 0.1"/>
      </geometry>
    </collision>
    <inertial>
      <mass value="0.05"/>
      <inertia ixx=".000038770" ixy=".0" ixz=".0" iyy=".000042198" iyz=".0" izz=".0000036030"/>
    </inertial>
  </link>
  <joint name="hip_front_leftR_link" type="fixed">
    <axis xyz="0 0 1"/>
    <parent link="motor_front_leftR_link"/>
    <child link="upper_leg_front_leftR_link"/>
    <origin rpy="-1.57075 0 0" xyz="0 .045 -.0145"/>
    <limit effort="100" velocity="100"/>
    <joint_properties damping="0.0" friction="0.0"/>
  </joint>
  <link name="upper_leg_front_leftL_link">
    <visual>
      <geometry>
        <box size="0.039 0.008 0.1"/>
      </geometry>
      <material name="legGrey"/>
    </visual>
    <collision>
      <geometry>
        <box size="0.039 0.008 0.1"/>
      </geometry>
    </collision>
    <inertial>
      <mass value="0.05"/>
      <inertia ixx=".000038770" ixy=".0" ixz=".0" iyy=".000042198" iyz=".0" izz=".0000036030"/>
    </inertial>
  </link>
  <joint name="motor_front_leftL_link" type="fixed">
    <axis xyz="0 0 1"/>
    <parent link="motor_front_leftL_link"/>
    <child link="upper_leg_front_leftL_link"/>
    <origin rpy="-1.57075 0 0" xyz="0 .045 .0145"/>
    <limit effort="100" velocity="100"/>
    <joint_properties damping="0.0" friction="0.0"/>
  </joint>
  <link name="upper_leg_back_rightR_link">
    <visual>
      <geometry>
        <box size="0.039 0.008 0.1"/>
      </geometry>
      <material name="legGrey"/>
    </visual>
    <collision>
      <geometry>
        <box size="0.039 0.008 0.1"/>
      </geometry>
    </collision>
    <inertial>
      <mass value="0.05"/>
      <inertia ixx=".000038770" ixy=".0" ixz=".0" iyy=".000042198" iyz=".0" izz=".0000036030"/>
    </inertial>
  </link>
  <joint name="hip_back_rightR_link" type="fixed">
    <axis xyz="0 0 1"/>
    <parent link="motor_back_rightR_link"/>
    <child link="upper_leg_back_rightR_link"/>
    <origin rpy="-1.57075 0 0" xyz="0 .045 -.0145"/>
    <limit effort="100" velocity="100"/>
    <joint_properties damping="0.0" friction="0.0"/>
  </joint>
  <link name="upper_leg_back_rightL_link">
    <visual>
      <geometry>
        <box size="0.039 0.008 0.1"/>
      </geometry>
      <material name="legGrey"/>
    </visual>
    <collision>
      <geometry>
        <box size="0.039 0.008 0.1"/>
      </geometry>
    </collision>
    <inertial>
      <mass value="0.05"/>
      <inertia ixx=".000038770" ixy=".0" ixz=".0" iyy=".000042198" iyz=".0" izz=".0000036030"/>
    </inertial>
  </link>
  <joint name="motor_back_rightL_link" type="fixed">
    <axis xyz="0 0 1"/>
    <parent link="motor_back_rightL_link"/>
    <child link="upper_leg_back_rightL_link"/>
    <origin rpy="-1.57075 0 0" xyz="0 .045 .0145"/>
    <limit effort="100" velocity="100"/>
    <joint_properties damping="0.0" friction="0.0"/>
  </joint>
  <link name="upper_leg_back_leftR_link">
    <visual>
      <geometry>
        <box size="0.039 0.008 0.1"/>
      </geometry>
      <material name="legGrey"/>
    </visual>
    <collision>
      <geometry>
        <box size="0.039 0.008 0.1"/>
      </geometry>
    </collision>
    <inertial>
      <mass value="0.05"/>
      <inertia ixx=".000038770" ixy=".0" ixz=".0" iyy=".000042198" iyz=".0" izz=".0000036030"/>
    </inertial>
  </link>
  <joint name="hip_back_leftR_link" type="fixed">
    <axis xyz="0 0 1"/>
    <parent link="motor_back_leftR_link"/>
    <child link="upper_leg_back_leftR_link"/>
    <origin rpy="-1.57075 0 0" xyz="0 .045 -.0145"/>
    <limit effort="100" velocity="100"/>
    <joint_properties damping="0.0" friction="0.0"/>
  </joint>
  <link name="upper_leg_back_leftL_link">
    <visual>
      <geometry>
        <box size="0.039 0.008 0.1"/>
      </geometry>
      <material name="legGrey"/>
    </visual>
    <collision>
      <geometry>
        <box size="0.039 0.008 0.1"/>
      </geometry>
    </collision>
    <inertial>
      <mass value="0.05"/>
      <inertia ixx=".000038770" ixy=".0" ixz=".0" iyy=".000042198" iyz=".0" izz=".0000036030"/>
    </inertial>
  </link>
  <joint name="motor_back_leftL_link" type="fixed">
    <axis xyz="0 0 1"/>
    <parent link="motor_back_leftL_link"/>
    <child link="upper_leg_back_leftL_link"/>
    <origin rpy="-1.57075 0 0" xyz="0 .045 .0145"/>
    <limit effort="100" velocity="100"/>
    <joint_properties damping="0.0" friction="0.0"/>
  </joint>
  <!-- Lower legs and flexy knee joints -->
  <link name="lower_leg_front_leftL_link">
    <contact>
      <friction_anchor/>
      <stiffness value="3000.0"/>
      <damping value="100.0"/>
      <spinning_friction value=".05"/>
      <lateral_friction value="1"/>
    </contact>
    <visual>
      <origin rpy="0 0 0" xyz="0 0 0.124"/>
      <geometry>
        <box size="0.017 0.009 0.248"/>
      </geometry>
      <material name="legGrey"/>
    </visual>
    <collision>
      <origin rpy="0 0 0" xyz="0 0 0.124"/>
      <geometry>
        <box size="0.017 0.009 0.248"/>
      </geometry>
    </collision>
    <inertial>
      <origin rpy="0 0 0" xyz="0 0 0.124"/>
      <mass value="0.05"/>
      <inertia ixx=".00032459" ixy=".0" ixz=".0" iyy=".00032637" iyz=".0" izz=".000002178"/>
    </inertial>
  </link>
  <joint name="8" type="continuous">
    <axis xyz="0 -1 0"/>
    <parent link="upper_leg_front_leftL_link"/>
    <child link="lower_leg_front_leftL_link"/>
    <origin rpy="0 0 0" xyz="0 -0.0085 0.05"/>
    <limit effort="100" velocity="100"/>
    <joint_properties damping="0.0" friction="0.0"/>
  </joint>
  <!-- Toe -->
  <link name="toe0">
    <contact>
      <friction_anchor/>
      <stiffness value="30000.0"/>
      <damping value="1000.0"/>
      <spinning_friction value="0.3"/>
      <lateral_friction value="0.7"/>
    </contact>
    <visual>
      <origin rpy="0 0 0" xyz="0 0 0"/>
      <geometry>
        <sphere radius="0.015"/>
      </geometry>
      <material name="black"/>
    </visual>
    <collision>
      <origin rpy="0 0 0" xyz="0 0 0"/>
      <geometry>
        <sphere radius="0.015"/>
      </geometry>
    </collision>
    <inertial>
      <mass value="0.01"/>
      <inertia ixx="0.000025" ixy="0" ixz="0" iyy="0.000025" iyz="0" izz="0.000025"/>
    </inertial>
  </link>
  <joint name="toe0" type="fixed">
    <parent link="lower_leg_front_leftL_link"/>
    <child link="toe0"/>
    <origin xyz="0 0 0.248"/>
    <dynamics damping="0.0" friction="0.0"/>
  </joint>
  <link name="lower_leg_front_leftR_link">
    <contact>
      <friction_anchor/>
      <stiffness value="3000.0"/>
      <damping value="100.0"/>
      <spinning_friction value=".05"/>
      <lateral_friction value="1"/>
    </contact>
    <visual>
      <origin rpy="0 0 0" xyz="0 0 0.1"/>
      <geometry>
        <box size="0.017 0.009 0.2"/>
      </geometry>
      <material name="legGrey"/>
    </visual>
    <collision>
      <origin rpy="0 0 0" xyz="0 0 0.1"/>
      <geometry>
        <box size="0.017 0.009 0.2"/>
      </geometry>
    </collision>
    <inertial>
      <origin rpy="0 0 0" xyz="0 0 0.1"/>
      <mass value="0.05"/>
      <inertia ixx=".00032459" ixy=".0" ixz=".0" iyy=".00032637" iyz=".0" izz=".000002178"/>
    </inertial>
  </link>
  <joint name="9" type="continuous">
    <axis xyz="0 1 0"/>
    <parent link="upper_leg_front_leftR_link"/>
    <child link="lower_leg_front_leftR_link"/>
    <origin rpy="0 0 0" xyz="0 0.0085 0.05"/>
    <limit effort="100" velocity="100"/>
    <joint_properties damping="0.0" friction="0.0"/>
  </joint>
  <link name="lower_leg_back_leftL_link">
    <contact>
      <friction_anchor/>
      <stiffness value="3000.0"/>
      <damping value="100.0"/>
      <spinning_friction value=".05"/>
      <lateral_friction value="1"/>
    </contact>
    <visual>
      <origin rpy="0 0 0" xyz="0 0 0.124"/>
      <geometry>
        <box size="0.017 0.009 0.248"/>
      </geometry>
      <material name="legGrey"/>
    </visual>
    <collision>
      <origin rpy="0 0 0" xyz="0 0 0.124"/>
      <geometry>
        <box size="0.017 0.009 0.248"/>
      </geometry>
    </collision>
    <inertial>
      <origin rpy="0 0 0" xyz="0 0 0.124"/>
      <mass value="0.05"/>
      <inertia ixx=".00032459" ixy=".0" ixz=".0" iyy=".00032637" iyz=".0" izz=".000002178"/>
    </inertial>
  </link>
  <joint name="10" type="continuous">
    <axis xyz="0 -1 0"/>
    <parent link="upper_leg_back_leftL_link"/>
    <child link="lower_leg_back_leftL_link"/>
    <origin rpy="0 0 0" xyz="0 -0.0085 0.05"/>
    <limit effort="100" velocity="100"/>
    <joint_properties damping="0.0" friction="0.0"/>
  </joint>
  <!-- Toe -->
  <link name="toe2">
    <contact>
      <friction_anchor/>
      <stiffness value="30000.0"/>
      <damping value="1000.0"/>
      <spinning_friction value="0.3"/>
      <lateral_friction value="0.7"/>
    </contact>
    <visual>
      <origin rpy="0 0 0" xyz="0 0 0"/>
      <geometry>
        <sphere radius="0.015"/>
      </geometry>
      <material name="black"/>
    </visual>
    <collision>
      <origin rpy="0 0 0" xyz="0 0 0"/>
      <geometry>
        <sphere radius="0.015"/>
      </geometry>
    </collision>
    <inertial>
      <mass value="0.01"/>
      <inertia ixx="0.000025" ixy="0" ixz="0" iyy="0.000025" iyz="0" izz="0.000025"/>
    </inertial>
  </link>
  <joint name="toe2" type="fixed">
    <parent link="lower_leg_back_leftL_link"/>
    <child link="toe2"/>
    <origin xyz="0 0 0.248"/>
    <dynamics damping="0.0" friction="0.0"/>
  </joint>
  <link name="lower_leg_back_leftR_link">
    <contact>
      <friction_anchor/>
      <stiffness value="3000.0"/>
      <damping value="100.0"/>
      <spinning_friction value=".05"/>
      <lateral_friction value="1"/>
    </contact>
    <visual>
      <origin rpy="0 0 0" xyz="0 0 0.1"/>
      <geometry>
        <box size="0.017 0.009 0.2"/>
      </geometry>
      <material name="legGrey"/>
    </visual>
    <collision>
      <origin rpy="0 0 0" xyz="0 0 0.1"/>
      <geometry>
        <box size="0.017 0.009 0.2"/>
      </geometry>
    </collision>
    <inertial>
      <origin rpy="0 0 0" xyz="0 0 0.1"/>
      <mass value="0.05"/>
      <inertia ixx=".00032459" ixy=".0" ixz=".0" iyy=".00032637" iyz=".0" izz=".000002178"/>
    </inertial>
  </link>
  <joint name="11" type="continuous">
    <axis xyz="0 1 0"/>
    <parent link="upper_leg_back_leftR_link"/>
    <child link="lower_leg_back_leftR_link"/>
    <origin rpy="0 0 0" xyz="0 0.0085 0.05"/>
    <limit effort="100" velocity="100"/>
    <joint_properties damping="0.0" friction="0.0"/>
  </joint>
  <link name="lower_leg_front_rightL_link">
    <contact>
      <friction_anchor/>
      <stiffness value="3000.0"/>
      <damping value="100.0"/>
      <spinning_friction value=".05"/>
      <lateral_friction value="1"/>
    </contact>
    <visual>
      <origin rpy="0 0 0" xyz="0 0 0.1"/>
      <geometry>
        <box size="0.017 0.009 0.2"/>
      </geometry>
      <material name="legGrey"/>
    </visual>
    <collision>
      <origin rpy="0 0 0" xyz="0 0 0.1"/>
      <geometry>
        <box size="0.017 0.009 0.2"/>
      </geometry>
    </collision>
    <inertial>
      <origin rpy="0 0 0" xyz="0 0 0.1"/>
      <mass value="0.05"/>
      <inertia ixx=".00032459" ixy=".0" ixz=".0" iyy=".00032637" iyz=".0" izz=".000002178"/>
    </inertial>
  </link>
  <joint name="12" type="continuous">
    <axis xyz="0 -1 0"/>
    <parent link="upper_leg_front_rightL_link"/>
    <child link="lower_leg_front_rightL_link"/>
    <origin rpy="0 0 0" xyz="0 -0.0085 0.05"/>
    <limit effort="100" velocity="100"/>
    <joint_properties damping="0.0" friction="0.0"/>
  </joint>
  <link name="lower_leg_front_rightR_link">
    <contact>
      <friction_anchor/>
      <stiffness value="3000.0"/>
      <damping value="100.0"/>
      <spinning_friction value=".05"/>
      <lateral_friction value="1"/>
    </contact>
    <visual>
      <origin rpy="0 0 0" xyz="0 0 0.124"/>
      <geometry>
        <box size="0.017 0.009 0.248"/>
      </geometry>
      <material name="legGrey"/>
    </visual>
    <collision>
      <origin rpy="0 0 0" xyz="0 0 0.124"/>
      <geometry>
        <box size="0.017 0.009 0.248"/>
      </geometry>
    </collision>
    <inertial>
      <origin rpy="0 0 0" xyz="0 0 0.124"/>
      <mass value="0.05"/>
      <inertia ixx=".00032459" ixy=".0" ixz=".0" iyy=".00032637" iyz=".0" izz=".000002178"/>
    </inertial>
  </link>
  <joint name="13" type="continuous">
    <axis xyz="0 1 0"/>
    <parent link="upper_leg_front_rightR_link"/>
    <child link="lower_leg_front_rightR_link"/>
    <origin rpy="0 0 0" xyz="0 0.0085 0.05"/>
    <limit effort="100" velocity="100"/>
    <joint_properties damping="0.0" friction="0.0"/>
  </joint>
  <!-- Toe -->
  <link name="toe5">
    <contact>
      <friction_anchor/>
      <stiffness value="30000.0"/>
      <damping value="1000.0"/>
      <spinning_friction value="0.3"/>
      <lateral_friction value="0.7"/>
    </contact>
    <visual>
      <origin rpy="0 0 0" xyz="0 0 0"/>
      <geometry>
        <sphere radius="0.015"/>
      </geometry>
      <material name="black"/>
    </visual>
    <collision>
      <origin rpy="0 0 0" xyz="0 0 0"/>
      <geometry>
        <sphere radius="0.015"/>
      </geometry>
    </collision>
    <inertial>
      <mass value="0.01"/>
      <inertia ixx="0.000025" ixy="0" ixz="0" iyy="0.000025" iyz="0" izz="0.000025"/>
    </inertial>
  </link>
  <joint name="toe5" type="fixed">
    <parent link="lower_leg_front_rightR_link"/>
    <child link="toe5"/>
    <origin xyz="0 0 0.248"/>
    <dynamics damping="0.0" friction="0.0"/>
  </joint>
  <link name="lower_leg_back_rightL_link">
    <contact>
      <friction_anchor/>
      <stiffness value="3000.0"/>
      <damping value="100.0"/>
      <spinning_friction value=".05"/>
      <lateral_friction value="1"/>
    </contact>
    <visual>
      <origin rpy="0 0 0" xyz="0 0 0.1"/>
      <geometry>
        <box size="0.017 0.009 0.2"/>
      </geometry>
      <material name="legGrey"/>
    </visual>
    <collision>
      <origin rpy="0 0 0" xyz="0 0 0.1"/>
      <geometry>
        <box size="0.017 0.009 0.2"/>
      </geometry>
    </collision>
    <inertial>
      <origin rpy="0 0 0" xyz="0 0 0.1"/>
      <mass value="0.05"/>
      <inertia ixx=".00032459" ixy=".0" ixz=".0" iyy=".00032637" iyz=".0" izz=".000002178"/>
    </inertial>
  </link>
  <joint name="14" type="continuous">
    <axis xyz="0 -1 0"/>
    <parent link="upper_leg_back_rightL_link"/>
    <child link="lower_leg_back_rightL_link"/>
    <origin rpy="0 0 0" xyz="0 -0.0085 0.05"/>
    <limit effort="100" velocity="100"/>
    <joint_properties damping="0.0" friction="0.0"/>
  </joint>
  <link name="lower_leg_back_rightR_link">
    <contact>
      <friction_anchor/>
      <stiffness value="3000.0"/>
      <damping value="100.0"/>
      <spinning_friction value=".05"/>
      <lateral_friction value="1"/>
    </contact>
    <visual>
      <origin rpy="0 0 0" xyz="0 0 0.124"/>
      <geometry>
        <box size="0.017 0.009 0.248"/>
      </geometry>
      <material name="legGrey"/>
    </visual>
    <collision>
      <origin rpy="0 0 0" xyz="0 0 0.124"/>
      <geometry>
        <box size="0.017 0.009 0.248"/>
      </geometry>
    </collision>
    <inertial>
      <origin rpy="0 0 0" xyz="0 0 0.124"/>
      <mass value="0.05"/>
      <inertia ixx=".00032459" ixy=".0" ixz=".0" iyy=".00032637" iyz=".0" izz=".000002178"/>
    </inertial>
  </link>
  <joint name="15" type="continuous">
    <axis xyz="0 1 0"/>
    <parent link="upper_leg_back_rightR_link"/>
    <child link="lower_leg_back_rightR_link"/>
    <origin rpy="0 0 0" xyz="0 0.0085 0.05"/>
    <limit effort="100" velocity="100"/>
    <joint_properties damping="0.0" friction="0.0"/>
  </joint>
  <!-- Toe -->
  <link name="toe7">
    <contact>
      <friction_anchor/>
      <stiffness value="30000.0"/>
      <damping value="1000.0"/>
      <spinning_friction value="0.3"/>
      <lateral_friction value="0.7"/>
    </contact>
    <visual>
      <origin rpy="0 0 0" xyz="0 0 0"/>
      <geometry>
        <sphere radius="0.015"/>
      </geometry>
      <material name="black"/>
    </visual>
    <collision>
      <origin rpy="0 0 0" xyz="0 0 0"/>
      <geometry>
        <sphere radius="0.015"/>
      </geometry>
    </collision>
    <inertial>
      <mass value="0.01"/>
      <inertia ixx="0.000025" ixy="0" ixz="0" iyy="0.000025" iyz="0" izz="0.000025"/>
    </inertial>
  </link>
  <joint name="toe7" type="fixed">
    <parent link="lower_leg_back_rightR_link"/>
    <child link="toe7"/>
    <origin xyz="0 0 0.248"/>
    <dynamics damping="0.0" friction="0.0"/>
  </joint>
</robot>

